<mujoco model="go1">
  <compiler angle="radian" meshdir="go1_meshes" autolimits="true"/>

  <option cone="elliptic" impratio="100"/>

  <!-- Default values -->
  <default>
    <!-- Defaults for class go1 -->
    <default class="go1">

      <geom friction="0.6" margin="0.001" condim="1"/>
      <joint axis="0 1 0" damping="0.5" armature="0.005"/>

      <!-- inheritrange=1 sets the limit on position controlled to joint limit-->
      <!-- <position kp="35" kv="0.0" forcerange="-23.7 23.7" inheritrange="1"/> -->
      <!-- ctrlrange: limits torque commanded to motor, forcerange: limit torque applied by motor-->
      <motor ctrlrange="-23.7 23.7" forcerange="-23.7 23.7"/>

      <!-- Defaults for class abduction -->
      <default class="abduction">
        <joint axis="1 0 0" damping="1" range="-0.863 0.863" frictionloss="0.3"/> <!-- Default joint is hinge -->
      </default>

      <!-- Defaults for class hip -->
      <default class="hip">
        <joint range="-0.686 4.501" frictionloss="0.3"/>
      </default>

      <!-- Defaults for class knee -->
      <default class="knee">
        <joint range="-2.818 -0.888" frictionloss="1.0"/>
        <position forcerange="-35.55 35.55"/>
      </default>

      <!-- Defaults for class visual -->
      <default class="visual">
        <geom type="mesh" contype="0" conaffinity="0" group="2" material="dark"/>
      </default>

      <!-- Defaults for class collision -->
      <!-- Geoms in this class are for collision only, not for dynamics-->
      <default class="collision">
        <geom group="3" type="capsule"/>

        <default class="hip_left1">
          <geom size="0.046 0.02" pos="0 0.045 0" quat="1 1 0 0" type="cylinder"/>
        </default>

        <default class="hip_left2">
          <geom size="0.031 0.02" pos="0 0.065 0" quat="1 1 0 0" type="cylinder"/>
        </default>

        <default class="hip_left3">
          <geom size="0.046 0.02" quat="1 1 0 0" type="cylinder"/>
        </default>

        <default class="hip_right1">
          <geom size="0.046 0.02" pos="0 -0.045 0" quat="1 1 0 0" type="cylinder"/>
        </default>

        <default class="hip_right2">
          <geom size="0.031 0.02" pos="0 -0.065 0" quat="1 1 0 0" type="cylinder"/>
        </default>

        <default class="hip_right3">
          <geom size="0.046 0.02" quat="1 1 0 0" type="cylinder"/>
        </default>

        <default class="thigh1">
          <geom size="0.015" fromto="-0.02 0 0 -0.02 0 -0.16"/>
        </default>

        <default class="thigh2">
          <geom size="0.015" fromto="0 0 0 -0.02 0 -0.1"/>
        </default>

        <default class="thigh3">
          <geom size="0.015" fromto="-0.02 0 -0.16 0 0 -0.2"/>
        </default>

        <default class="calf1">
          <geom size="0.01" fromto="0 0 0 0.02 0 -0.13"/>
        </default>

        <default class="calf2">
          <geom size="0.01" fromto="0.02 0 -0.13 0 0 -0.2"/>
        </default>

        <default class="foot">
          <geom type="sphere" size="0.023" pos="0 0 -0.213" solimp="0.9 .95 0.023" condim="3"/>
        </default>

      </default>
    </default>
  </default>

  <!-- Define assets -->
  <asset>
    <material name="dark" rgba="0.2 0.2 0.2 1"/>
    <mesh class="go1" file="trunk.stl"/>
    <mesh class="go1" file="hip.stl"/>
    <mesh class="go1" file="thigh_mirror.stl"/>
    <mesh class="go1" file="calf.stl"/>
    <mesh class="go1" file="thigh.stl"/>
  </asset>

  <!-- Define bodies - most important! -->
  <!-- World -> trunk -> hip -> thigh -> calf -->
  <worldbody>
    <light name="spotlight" mode="targetbodycom" target="trunk" pos="0 -1 2"/>

    <!-- Trunk body -->
    <body name="trunk" pos="0 0 0.445" childclass="go1">
      <!-- Cameras to track CoM -->
      <camera name="track" pos="0.846 -1.3 0.316" xyaxes="0.866 0.500 0.000 -0.171 0.296 0.940" mode="trackcom"/>
      <camera name="top" pos="-1 0 1" xyaxes="0 -1 0 0.7 0 0.7" mode="trackcom"/>
      <camera name="side" pos="0 -1 .3" xyaxes="1 0 0 0 1 2" mode="trackcom"/>
      <camera name="back" pos="-1 0 .3" xyaxes="0 -1 0 1 0 2" mode="trackcom"/>
      
      <!-- Location of head: <site> is for representing location of interest and it doesn't affect dynamics or collisions -->
      <site name="head" pos="0.3 0 0" rgba="1 0 0 1" size="0.02" group="5"/>

      <inertial pos="0.0223 0.002 -0.0005" quat="-0.00342088 0.705204 0.000106698 0.708996" mass="5.204"
        diaginertia="0.0716565 0.0630105 0.0168101"/>

      <!-- Trunk is a free joint (free body with 6 d.o.f), placed at CoM -->
      <freejoint/>
      <!-- Visual is from mesh -->
      <geom class="visual" mesh="trunk"/>
      <!-- Collision is from primitives -->
      <geom class="collision" size="0.125 0.04 0.057" type="box"/>
      <geom class="collision" quat="1 0 1 0" pos="0 -0.04 0" size="0.058 0.125" type="cylinder"/>
      <geom class="collision" quat="1 0 1 0" pos="0 +0.04 0" size="0.058 0.125" type="cylinder"/>
      <geom class="collision" pos="0.25 0 0" size="0.005 0.06 0.05" type="box"/>
      <geom class="collision" pos="0.25 0.06 -0.01" size="0.009 0.035"/>
      <geom class="collision" pos="0.25 -0.06 -0.01" size="0.009 0.035"/>
      <geom class="collision" pos="0.25 0 -0.05" size="0.01 0.06" quat="1 1 0 0"/>
      <geom class="collision" pos="0.255 0 0.0355" size="0.021 0.052" quat="1 1 0 0"/>
      <!-- Location for imu -->
      <site name="imu" pos="0 0 0"/>

      <!-- FR hip body -->
      <body name="FR_hip" pos="0.1881 -0.04675 0">
        <inertial pos="-0.0049166 0.00762615 -8.865e-05" quat="0.507341 0.514169 0.495027 0.482891" mass="0.68"
          diaginertia="0.000734064 0.000468438 0.000398719"/>
        <!-- joint -->
        <joint class="abduction" name="FR_hip_joint"/>
        <!-- Visual from mesh -->
        <geom class="visual" mesh="hip" quat="1 0 0 0"/>
        <!-- Collision from primitives (using defaults)-->
        <geom class="hip_right1"/>
        <geom class="hip_right2"/>

        <!-- FR thigh body -->
        <body name="FR_thigh" pos="0 -0.08 0">
          <inertial pos="-0.00304722 0.019315 -0.0305004" quat="0.65243 -0.0272313 0.0775126 0.753383" mass="1.009"
            diaginertia="0.00478717 0.00460903 0.000709268"/>
          <!-- Joint -->
          <joint class="hip" name="FR_thigh_joint"/>
          <!-- Visual from mesh-->
          <geom class="visual" mesh="thigh_mirror"/>
          <!-- Collision from primitives (using defaults) -->
          <geom class="thigh1"/>
          <geom class="thigh2"/>
          <geom class="thigh3"/>

          <!-- FR calf body -->
          <body name="FR_calf" pos="0 0 -0.213">
            <inertial pos="0.00429862 0.000976676 -0.146197" quat="0.691246 0.00357467 0.00511118 0.722592"
              mass="0.195862" diaginertia="0.00149767 0.00148468 3.58427e-05"/>
            <!-- Joint -->
            <joint class="knee" name="FR_calf_joint"/>
            <!-- Visual from mesh -->
            <geom class="visual" mesh="calf"/>
            <!-- Collision from primitives (using defaults)-->
            <geom class="calf1"/>
            <geom class="calf2"/>

            <!-- FR foot: not a separate body but welded to the calf -->
            <!-- Collision from primitive (using defaults) -->
            <geom name="FR" class="foot"/>
            <site name="FR" pos="0 0 -0.213" type="sphere" size="0.023" group="5"/>
          </body>
        </body>
      </body>

      <!-- FL bodies -->
      <body name="FL_hip" pos="0.1881 0.04675 0">
        <inertial pos="-0.0049166 -0.00762615 -8.865e-05" quat="0.482891 0.495027 0.514169 0.507341" mass="0.68"
          diaginertia="0.000734064 0.000468438 0.000398719"/>
        <joint class="abduction" name="FL_hip_joint"/>
        <geom class="visual" mesh="hip"/>
        <geom class="hip_left1"/>
        <geom class="hip_left2"/>
        <body name="FL_thigh" pos="0 0.08 0">
          <inertial pos="-0.00304722 -0.019315 -0.0305004" quat="0.753383 0.0775126 -0.0272313 0.65243" mass="1.009"
            diaginertia="0.00478717 0.00460903 0.000709268"/>
          <joint class="hip" name="FL_thigh_joint"/>
          <geom class="visual" mesh="thigh"/>
          <geom class="thigh1"/>
          <geom class="thigh2"/>
          <geom class="thigh3"/>
          <body name="FL_calf" pos="0 0 -0.213">
            <inertial pos="0.00429862 0.000976676 -0.146197" quat="0.691246 0.00357467 0.00511118 0.722592"
              mass="0.195862" diaginertia="0.00149767 0.00148468 3.58427e-05"/>
            <joint class="knee" name="FL_calf_joint"/>
            <geom class="visual" mesh="calf"/>
            <geom class="calf1"/>
            <geom class="calf2"/>
            <geom name="FL" class="foot"/>
            <site name="FL" pos="0 0 -0.213" type="sphere" size="0.023" group="5"/>
          </body>
        </body>
      </body>

      <!-- RR bodies -->
      <body name="RR_hip" pos="-0.1881 -0.04675 0">
        <inertial pos="0.0049166 0.00762615 -8.865e-05" quat="0.495027 0.482891 0.507341 0.514169" mass="0.68"
          diaginertia="0.000734064 0.000468438 0.000398719"/>
        <joint class="abduction" name="RR_hip_joint"/>
        <geom class="visual" quat="0 0 0 -1" mesh="hip"/>
        <geom class="hip_right1"/>
        <geom class="hip_right2"/>
        <geom class="hip_right3"/>
        <body name="RR_thigh" pos="0 -0.08 0">
          <inertial pos="-0.00304722 0.019315 -0.0305004" quat="0.65243 -0.0272313 0.0775126 0.753383" mass="1.009"
            diaginertia="0.00478717 0.00460903 0.000709268"/>
          <joint class="hip" name="RR_thigh_joint"/>
          <geom class="visual" mesh="thigh_mirror"/>
          <geom class="thigh1"/>
          <geom class="thigh2"/>
          <geom class="thigh3"/>
          <body name="RR_calf" pos="0 0 -0.213">
            <inertial pos="0.00429862 0.000976676 -0.146197" quat="0.691246 0.00357467 0.00511118 0.722592"
              mass="0.195862" diaginertia="0.00149767 0.00148468 3.58427e-05"/>
            <joint class="knee" name="RR_calf_joint"/>
            <geom class="visual" mesh="calf"/>
            <geom class="calf1"/>
            <geom class="calf2"/>
            <geom name="RR" class="foot"/>
            <site name="RR" pos="0 0 -0.213" type="sphere" size="0.023" group="5"/>
          </body>
        </body>
      </body>

      <!-- RL bodies -->
      <body name="RL_hip" pos="-0.1881 0.04675 0">
        <inertial pos="0.0049166 -0.00762615 -8.865e-05" quat="0.514169 0.507341 0.482891 0.495027" mass="0.68"
          diaginertia="0.000734064 0.000468438 0.000398719"/>
        <joint class="abduction" name="RL_hip_joint"/>
        <geom class="visual" quat="0 0 1 0" mesh="hip"/>
        <geom class="hip_left1"/>
        <geom class="hip_left2"/>
        <geom class="hip_left3"/>
        <body name="RL_thigh" pos="0 0.08 0">
          <inertial pos="-0.00304722 -0.019315 -0.0305004" quat="0.753383 0.0775126 -0.0272313 0.65243" mass="1.009"
            diaginertia="0.00478717 0.00460903 0.000709268"/>
          <joint class="hip" name="RL_thigh_joint"/>
          <geom class="visual" mesh="thigh"/>
          <geom class="thigh1"/>
          <geom class="thigh2"/>
          <geom class="thigh3"/>
          <body name="RL_calf" pos="0 0 -0.213">
            <inertial pos="0.00429862 0.000976676 -0.146197" quat="0.691246 0.00357467 0.00511118 0.722592"
              mass="0.195862" diaginertia="0.00149767 0.00148468 3.58427e-05"/>
            <joint class="knee" name="RL_calf_joint"/>
            <geom class="visual" mesh="calf"/>
            <geom class="calf1"/>
            <geom class="calf2"/>
            <geom name="RL" class="foot"/>
            <site name="RL" pos="0 0 -0.213" type="sphere" size="0.023" group="5"/>
          </body>
        </body>
      </body>
    </body>
  </worldbody>

  <actuator>
    <!--
      We're controlling the positions of the actuators, and transmit torque via a PD controller
      if we're controlling torques directly, we need to specify the gear ratios.
    -->
    <!-- Using default values for actuators -->
    <!-- The <joint> specifies which joint the actuator applies to -->
    <motor class="abduction" name="FR_hip" joint="FR_hip_joint"/>
    <motor class="hip" name="FR_thigh" joint="FR_thigh_joint"/>
    <motor class="knee" name="FR_calf" joint="FR_calf_joint"/>
    <motor class="abduction" name="FL_hip" joint="FL_hip_joint"/>
    <motor class="hip" name="FL_thigh" joint="FL_thigh_joint"/>
    <motor class="knee" name="FL_calf" joint="FL_calf_joint"/>
    <motor class="abduction" name="RR_hip" joint="RR_hip_joint"/>
    <motor class="hip" name="RR_thigh" joint="RR_thigh_joint"/>
    <motor class="knee" name="RR_calf" joint="RR_calf_joint"/>
    <motor class="abduction" name="RL_hip" joint="RL_hip_joint"/>
    <motor class="hip" name="RL_thigh" joint="RL_thigh_joint"/>
    <motor class="knee" name="RL_calf" joint="RL_calf_joint"/>
  </actuator>

  <!-- Sensors -->
  <sensor>
      <gyro site="imu" name="gyro"/>
      <velocimeter site="imu" name="local_linvel"/>
      <accelerometer site="imu" name="accelerometer"/>
      <framepos objtype="site" objname="imu" name="position"/>
      <framezaxis objtype="site" objname="imu" name="upvector"/>
      <framexaxis objtype="site" objname="imu" name="forwardvector"/>
      <framelinvel objtype="site" objname="imu" name="global_linvel"/>
      <frameangvel objtype="site" objname="imu" name="global_angvel"/>
      <framequat objtype="site" objname="imu" name="orientation"/>
      <framelinvel objtype="site" objname="FR" name="FR_global_linvel"/>
      <framelinvel objtype="site" objname="FL" name="FL_global_linvel"/>
      <framelinvel objtype="site" objname="RR" name="RR_global_linvel"/>
      <framelinvel objtype="site" objname="RL" name="RL_global_linvel"/>
      <framepos objtype="site" objname="FR" name="FR_pos" reftype="site" refname="imu"/>
      <framepos objtype="site" objname="FL" name="FL_pos" reftype="site" refname="imu"/>
      <framepos objtype="site" objname="RR" name="RR_pos" reftype="site" refname="imu"/>
      <framepos objtype="site" objname="RL" name="RL_pos" reftype="site" refname="imu"/>
      <framepos objtype="site" objname="head" name="head_pos"/>
      <contact name="FR_floor_found" geom1="FR" geom2="floor" reduce="mindist" num="1" data="found"/>
      <contact name="FL_floor_found" geom1="FL" geom2="floor" reduce="mindist" num="1" data="found"/>
      <contact name="RR_floor_found" geom1="RR" geom2="floor" reduce="mindist" num="1" data="found"/>
      <contact name="RL_floor_found" geom1="RL" geom2="floor" reduce="mindist" num="1" data="found"/>
    </sensor>

  <!-- Initial values -->
  <keyframe>
    <key name="home" qpos="0 0 0.35 1 0 0 0 0.0 0.8 -1.5 0.0 0.8 -1.5 0.0 0.8 -1.5 0.0 0.8 -1.5"
      ctrl="0 0 0 0 0 0 0 0 0 0 0 0"/>
  </keyframe>
</mujoco>
